Workbook

Sheet Resumen
B2: Análisis Comparativo de Estructuras de Datos de Inventario
B4: Tiempo Promedio de Ejecución (s)
B5: m | C5: BST (s) | D5: RedBlackBST (s)
B6: 4096 | C6: ='Inv_4096'!C6 -> 0 | D6: ='Inv_4096'!D6 -> 0
B7: 8192 | C7: ='Inv_8192'!C6 -> 0 | D7: ='Inv_8192'!D6 -> 0
B8: 16384 | C8: ='Inv_16384'!C6 -> 0 | D8: ='Inv_16384'!D6 -> 0
B9: 32768 | C9: ='Inv_32768'!C6 -> 0 | D9: ='Inv_32768'!D6 -> 0
B10: 65536 | C10: ='Inv_65536'!C6 -> 0 | D10: ='Inv_65536'!D6 -> 0
B11: 131072 | C11: ='Inv_131072'!C6 -> 0 | D11: ='Inv_131072'!D6 -> 0
B12: 262144 | C12: ='Inv_262144'!C6 -> 0 | D12: ='Inv_262144'!D6 -> 0
B13: 524288 | C13: ='Inv_524288'!C6 -> 0 | D13: ='Inv_524288'!D6 -> 0
B15: Altura Promedio de los Árboles
B16: m | C16: BST | D16: RedBlackBST
B17: 4096 | C17: ='Inv_4096'!C9 -> 0 | D17: ='Inv_4096'!D9 -> 0
B18: 8192 | C18: ='Inv_8192'!C9 -> 0 | D18: ='Inv_8192'!D9 -> 0
B19: 16384 | C19: ='Inv_16384'!C9 -> 0 | D19: ='Inv_16384'!D9 -> 0
B20: 32768 | C20: ='Inv_32768'!C9 -> 0 | D20: ='Inv_32768'!D9 -> 0
B21: 65536 | C21: ='Inv_65536'!C9 -> 0 | D21: ='Inv_65536'!D9 -> 0
B22: 131072 | C22: ='Inv_131072'!C9 -> 0 | D22: ='Inv_131072'!D9 -> 0
B23: 262144 | C23: ='Inv_262144'!C9 -> 0 | D23: ='Inv_262144'!D9 -> 0
B24: 524288 | C24: ='Inv_524288'!C9 -> 0 | D24: ='Inv_524288'!D9 -> 0
B27: Métricas de Crecimiento de Tiempos (2m / m)
B28: Intervalo | C28: Ratio BST | D28: log2(Ratio) BST | E28: Ratio RB | F28: log2(Ratio) RB
B29: 4096 -> 8192 | C29: =C7/C6 -> 0 | D29: =LOG(C29, 2) -> 0 | E29: =D7/D6 -> 0 | F29: =LOG(E29, 2) -> 0
B30: 8192 -> 16384 | C30: =C8/C7 -> 0 | D30: =LOG(C30, 2) -> 0 | E30: =D8/D7 -> 0 | F30: =LOG(E30, 2) -> 0
B31: 16384 -> 32768 | C31: =C9/C8 -> 0 | D31: =LOG(C31, 2) -> 0 | E31: =D9/D8 -> 0 | F31: =LOG(E31, 2) -> 0
B32: 32768 -> 65536 | C32: =C10/C9 -> 0 | D32: =LOG(C32, 2) -> 0 | E32: =D10/D9 -> 0 | F32: =LOG(E32, 2) -> 0
B33: 65536 -> 131072 | C33: =C11/C10 -> 0 | D33: =LOG(C33, 2) -> 0 | E33: =D11/D10 -> 0 | F33: =LOG(E33, 2) -> 0
B34: 131072 -> 262144 | C34: =C12/C11 -> 0 | D34: =LOG(C34, 2) -> 0 | E34: =D12/D11 -> 0 | F34: =LOG(E34, 2) -> 0
B35: 262144 -> 524288 | C35: =C13/C12 -> 0 | D35: =LOG(C35, 2) -> 0 | E35: =D13/D12 -> 0 | F35: =LOG(E35, 2) -> 0
B37: Promedio de Operaciones Exitosas y Fallidas
B38: m | C38: Estructura | D38: Cons. Exitosa | E38: Cons. Fallida | F38: Prést. Exitoso | G38: Prést. Fallido | H38: Dev. Exitosa | I38: Dev. Fallida
B39: 4096 | C39: BST | D39: =AVERAGE('Inv_4096'!J14:J43) -> 0 | E39: =AVERAGE('Inv_4096'!K14:K43) -> 0 | F39: =AVERAGE('Inv_4096'!L14:L43) -> 0 | G39: =AVERAGE('Inv_4096'!M14:M43) -> 0 | H39: =AVERAGE('Inv_4096'!N14:N43) -> 0 | I39: =AVERAGE('Inv_4096'!O14:O43) -> 0
B40: 4096 | C40: RedBlackBST | D40: =AVERAGE('Inv_4096'!Z14:Z43) -> 0 | E40: =AVERAGE('Inv_4096'!AA14:AA43) -> 0 | F40: =AVERAGE('Inv_4096'!AB14:AB43) -> 0 | G40: =AVERAGE('Inv_4096'!AC14:AC43) -> 0 | H40: =AVERAGE('Inv_4096'!AD14:AD43) -> 0 | I40: =AVERAGE('Inv_4096'!AE14:AE43) -> 0
B41: 8192 | C41: BST | D41: =AVERAGE('Inv_8192'!J14:J43) -> 0 | E41: =AVERAGE('Inv_8192'!K14:K43) -> 0 | F41: =AVERAGE('Inv_8192'!L14:L43) -> 0 | G41: =AVERAGE('Inv_8192'!M14:M43) -> 0 | H41: =AVERAGE('Inv_8192'!N14:N43) -> 0 | I41: =AVERAGE('Inv_8192'!O14:O43) -> 0
B42: 8192 | C42: RedBlackBST | D42: =AVERAGE('Inv_8192'!Z14:Z43) -> 0 | E42: =AVERAGE('Inv_8192'!AA14:AA43) -> 0 | F42: =AVERAGE('Inv_8192'!AB14:AB43) -> 0 | G42: =AVERAGE('Inv_8192'!AC14:AC43) -> 0 | H42: =AVERAGE('Inv_8192'!AD14:AD43) -> 0 | I42: =AVERAGE('Inv_8192'!AE14:AE43) -> 0
B43: 16384 | C43: BST | D43: =AVERAGE('Inv_16384'!J14:J43) -> 0 | E43: =AVERAGE('Inv_16384'!K14:K43) -> 0 | F43: =AVERAGE('Inv_16384'!L14:L43) -> 0 | G43: =AVERAGE('Inv_16384'!M14:M43) -> 0 | H43: =AVERAGE('Inv_16384'!N14:N43) -> 0 | I43: =AVERAGE('Inv_16384'!O14:O43) -> 0
B44: 16384 | C44: RedBlackBST | D44: =AVERAGE('Inv_16384'!Z14:Z43) -> 0 | E44: =AVERAGE('Inv_16384'!AA14:AA43) -> 0 | F44: =AVERAGE('Inv_16384'!AB14:AB43) -> 0 | G44: =AVERAGE('Inv_16384'!AC14:AC43) -> 0 | H44: =AVERAGE('Inv_16384'!AD14:AD43) -> 0 | I44: =AVERAGE('Inv_16384'!AE14:AE43) -> 0
B45: 32768 | C45: BST | D45: =AVERAGE('Inv_32768'!J14:J43) -> 0 | E45: =AVERAGE('Inv_32768'!K14:K43) -> 0 | F45: =AVERAGE('Inv_32768'!L14:L43) -> 0 | G45: =AVERAGE('Inv_32768'!M14:M43) -> 0 | H45: =AVERAGE('Inv_32768'!N14:N43) -> 0 | I45: =AVERAGE('Inv_32768'!O14:O43) -> 0
B46: 32768 | C46: RedBlackBST | D46: =AVERAGE('Inv_32768'!Z14:Z43) -> 0 | E46: =AVERAGE('Inv_32768'!AA14:AA43) -> 0 | F46: =AVERAGE('Inv_32768'!AB14:AB43) -> 0 | G46: =AVERAGE('Inv_32768'!AC14:AC43) -> 0 | H46: =AVERAGE('Inv_32768'!AD14:AD43) -> 0 | I46: =AVERAGE('Inv_32768'!AE14:AE43) -> 0
...

Sheet Inv_4096
A1: Resultados de Simulación para m = 4096
B3: Estadísticas de Tiempos y Alturas
B4: Métrica | C4: BST | D4: RedBlackBST
B5: Tiempo Mínimo (s) | C5: =MIN(B14:B43) -> 0 | D5: =MIN(R14:R43) -> 0
B6: Tiempo Máximo (s) | C6: =MAX(B14:B43) -> 0 | D6: =MAX(R14:R43) -> 0
B7: Tiempo Promedio (s) | C7: =AVERAGE(B14:B43) -> 0 | D7: =AVERAGE(R14:R43) -> 0
B8: Desviación Estándar (s) | C8: =STDEV.S(B14:B43) -> 0 | D8: =STDEV.S(R14:R43) -> 0
B9: Coeficiente de Variación | C9: =C7/C6 -> 0 | D9: =D7/D6 -> 0
B10: Altura Promedio | C10: =AVERAGE(C14:C43) -> 0 | D10: =AVERAGE(S14:S43) -> 0
B11: Altura Máxima | C11: =MAX(C14:C43) -> 0 | D11: =MAX(S14:S43) -> 0
A12: Microdatos de BST (30 Ejecuciones) | Q12: Microdatos de RedBlackBST (30 Ejecuciones)
A13: Instancia | B13: Tiempo (s) | C13: Altura Final | D13: Tamaño Final | E13: Compra Tot | F13: Cons Tot | G13: Prést Tot | H13: Dev Tot | I13: Baja Tot | J13: Cons Exit | K13: Cons Fall | L13: Prést Exit | M13: Prést Fall | N13: Dev Exit | O13: Dev Fall | Q13: Instancia | R13: Tiempo (s) | S13: Altura Final | T13: Tamaño Final | U13: Compra Tot | V13: Cons Tot | W13: Prést Tot | X13: Dev Tot | Y13: Baja Tot | Z13: Cons Exit | AA13: Cons Fall | AB13: Prést Exit | AC13: Prést Fall | AD13: Dev Exit | AE13: Dev Fall
A14: 1 | B14: 0.004773 | C14: 23 | D14: 1335 | E14: 1413 | F14: 1208 | G14: 648 | H14: 418 | I14: 409 | J14: 61 | K14: 1147 | L14: 21 | M14: 627 | N14: 0 | O14: 418 | Q14: 1 | R14: 0.005284 | S14: 13 | T14: 1335 | U14: 1413 | V14: 1208 | W14: 648 | X14: 418 | Y14: 409 | Z14: 61 | AA14: 1147 | AB14: 21 | AC14: 627 | AD14: 0 | AE14: 418
A15: 2 | B15: 0.002309 | C15: 21 | D15: 1336 | E15: 1430 | F15: 1250 | G15: 597 | H15: 418 | I15: 401 | J15: 56 | K15: 1194 | L15: 21 | M15: 576 | N15: 0 | O15: 418 | Q15: 2 | R15: 0.003326 | S15: 13 | T15: 1336 | U15: 1430 | V15: 1250 | W15: 597 | X15: 418 | Y15: 401 | Z15: 56 | AA15: 1194 | AB15: 21 | AC15: 576 | AD15: 0 | AE15: 418
A16: 3 | B16: 0.002441 | C16: 22 | D16: 1373 | E16: 1447 | F16: 1226 | G16: 613 | H16: 399 | I16: 411 | J16: 61 | K16: 1165 | L16: 25 | M16: 588 | N16: 0 | O16: 399 | Q16: 3 | R16: 0.002481 | S16: 13 | T16: 1373 | U16: 1447 | V16: 1226 | W16: 613 | X16: 399 | Y16: 411 | Z16: 61 | AA16: 1165 | AB16: 25 | AC16: 588 | AD16: 0 | AE16: 399
A17: 4 | B17: 0.002629 | C17: 20 | D17: 1342 | E17: 1413 | F17: 1235 | G17: 614 | H17: 432 | I17: 402 | J17: 57 | K17: 1178 | L17: 20 | M17: 594 | N17: 0 | O17: 432 | Q17: 4 | R17: 0.002395 | S17: 13 | T17: 1342 | U17: 1413 | V17: 1235 | W17: 614 | X17: 432 | Y17: 402 | Z17: 57 | AA17: 1178 | AB17: 20 | AC17: 594 | AD17: 0 | AE17: 432
A18: 5 | B18: 0.002348 | C18: 21 | D18: 1369 | E18: 1444 | F18: 1242 | G18: 604 | H18: 404 | I18: 402 | J18: 49 | K18: 1193 | L18: 16 | M18: 588 | N18: 0 | O18: 404 | Q18: 5 | R18: 0.002434 | S18: 13 | T18: 1369 | U18: 1444 | V18: 1242 | W18: 604 | X18: 404 | Y18: 402 | Z18: 49 | AA18: 1193 | AB18: 16 | AC18: 588 | AD18: 0 | AE18: 404
A19: 6 | B19: 0.002295 | C19: 25 | D19: 1363 | E19: 1455 | F19: 1225 | G19: 628 | H19: 370 | I19: 418 | J19: 49 | K19: 1176 | L19: 20 | M19: 608 | N19: 0 | O19: 370 | Q19: 6 | R19: 0.002273 | S19: 13 | T19: 1363 | U19: 1455 | V19: 1225 | W19: 628 | X19: 370 | Y19: 418 | Z19: 49 | AA19: 1176 | AB19: 20 | AC19: 608 | AD19: 0 | AE19: 370
A20: 7 | B20: 0.00232 | C20: 22 | D20: 1320 | E20: 1395 | F20: 1234 | G20: 666 | H20: 391 | I20: 410 | J20: 43 | K20: 1191 | L20: 25 | M20: 641 | N20: 0 | O20: 391 | Q20: 7 | R20: 0.002304 | S20: 13 | T20: 1320 | U20: 1395 | V20: 1234 | W20: 666 | X20: 391 | Y20: 410 | Z20: 43 | AA20: 1191 | AB20: 25 | AC20: 641 | AD20: 0 | AE20: 391
A21: 8 | B21: 0.002246 | C21: 21 | D21: 1385 | E21: 1470 | F21: 1220 | G21: 613 | H21: 418 | I21: 375 | J21: 70 | K21: 1150 | L21: 25 | M21: 588 | N21: 0 | O21: 418 | Q21: 8 | R21: 0.002368 | S21: 14 | T21: 1385 | U21: 1470 | V21: 1220 | W21: 613 | X21: 418 | Y21: 375 | Z21: 70 | AA21: 1150 | AB21: 25 | AC21: 588 | AD21: 0 | AE21: 418
A22: 9 | B22: 0.002069 | C22: 21 | D22: 1362 | E22: 1427 | F22: 1253 | G22: 628 | H22: 379 | I22: 409 | J22: 53 | K22: 1200 | L22: 19 | M22: 609 | N22: 0 | O22: 379 | Q22: 9 | R22: 0.001459 | S22: 13 | T22: 1362 | U22: 1427 | V22: 1253 | W22: 628 | X22: 379 | Y22: 409 | Z22: 53 | AA22: 1200 | AB22: 19 | AC22: 609 | AD22: 0 | AE22: 379
A23: 10 | B23: 0.001347 | C23: 21 | D23: 1372 | E23: 1432 | F23: 1245 | G23: 635 | H23: 421 | I23: 363 | J23: 59 | K23: 1186 | L23: 20 | M23: 615 | N23: 0 | O23: 421 | Q23: 10 | R23: 0.001092 | S23: 13 | T23: 1372 | U23: 1432 | V23: 1245 | W23: 635 | X23: 421 | Y23: 363 | Z23: 59 | AA23: 1186 | AB23: 20 | AC23: 615 | AD23: 0 | AE23: 421
A24: 11 | B24: 0.001148 | C24: 20 | D24: 1409 | E24: 1487 | F24: 1200 | G24: 593 | H24: 401 | I24: 415 | J24: 62 | K24: 1138 | L24: 21 | M24: 572 | N24: 0 | O24: 401 | Q24: 11 | R24: 0.001124 | S24: 14 | T24: 1409 | U24: 1487 | V24: 1200 | W24: 593 | X24: 401 | Y24: 415 | Z24: 62 | AA24: 1138 | AB24: 21 | AC24: 572 | AD24: 0 | AE24: 401
A25: 12 | B25: 0.001064 | C25: 22 | D25: 1385 | E25: 1473 | F25: 1221 | G25: 637 | H25: 398 | I25: 367 | J25: 58 | K25: 1163 | L25: 30 | M25: 607 | N25: 0 | O25: 398 | Q25: 12 | R25: 0.001093 | S25: 12 | T25: 1385 | U25: 1473 | V25: 1221 | W25: 637 | X25: 398 | Y25: 367 | Z25: 58 | AA25: 1163 | AB25: 30 | AC25: 607 | AD25: 0 | AE25: 398
... A43: 30 | B43: 0.000963 | C43: 24 | D43: 1391 | E43: 1464 | F43: 1224 | G43: 577 | H43: 420 | I43: 411 | J43: 52 | K43: 1172 | L43: 27 | M43: 550 | N43: 0 | O43: 420 | Q43: 30 | R43: 0.001 | S43: 13 | T43: 1391 | U43: 1464 | V43: 1224 | W43: 577 | X43: 420 | Y43: 411 | Z43: 52 | AA43: 1172 | AB43: 27 | AC43: 550 | AD43: 0 | AE43: 420

Sheet Inv_8192
A1: Resultados de Simulación para m = 8192
B3: Estadísticas de Tiempos y Alturas
B4: Métrica | C4: BST | D4: RedBlackBST
B5: Tiempo Mínimo (s) | C5: =MIN(B14:B43) -> 0 | D5: =MIN(R14:R43) -> 0
B6: Tiempo Máximo (s) | C6: =MAX(B14:B43) -> 0 | D6: =MAX(R14:R43) -> 0
B7: Tiempo Promedio (s) | C7: =AVERAGE(B14:B43) -> 0 | D7: =AVERAGE(R14:R43) -> 0
B8: Desviación Estándar (s) | C8: =STDEV.S(B14:B43) -> 0 | D8: =STDEV.S(R14:R43) -> 0
B9: Coeficiente de Variación | C9: =C7/C6 -> 0 | D9: =D7/D6 -> 0
B10: Altura Promedio | C10: =AVERAGE(C14:C43) -> 0 | D10: =AVERAGE(S14:S43) -> 0
B11: Altura Máxima | C11: =MAX(C14:C43) -> 0 | D11: =MAX(S14:S43) -> 0
A12: Microdatos de BST (30 Ejecuciones) | Q12: Microdatos de RedBlackBST (30 Ejecuciones)
A13: Instancia | B13: Tiempo (s) | C13: Altura Final | D13: Tamaño Final | E13: Compra Tot | F13: Cons Tot | G13: Prést Tot | H13: Dev Tot | I13: Baja Tot | J13: Cons Exit | K13: Cons Fall | L13: Prést Exit | M13: Prést Fall | N13: Dev Exit | O13: Dev Fall | Q13: Instancia | R13: Tiempo (s) | S13: Altura Final | T13: Tamaño Final | U13: Compra Tot | V13: Cons Tot | W13: Prést Tot | X13: Dev Tot | Y13: Baja Tot | Z13: Cons Exit | AA13: Cons Fall | AB13: Prést Exit | AC13: Prést Fall | AD13: Dev Exit | AE13: Dev Fall
A14: 1 | B14: 0.002119 | C14: 22 | D14: 2691 | E14: 2844 | F14: 2458 | G14: 1250 | H14: 819 | I14: 821 | J14: 104 | K14: 2354 | L14: 53 | M14: 1197 | N14: 0 | O14: 819 | Q14: 1 | R14: 0.002151 | S14: 14 | T14: 2691 | U14: 2844 | V14: 2458 | W14: 1250 | X14: 819 | Y14: 821 | Z14: 104 | AA14: 2354 | AB14: 53 | AC14: 1197 | AD14: 0 | AE14: 819
A15: 2 | B15: 0.002253 | C15: 23 | D15: 2680 | E15: 2826 | F15: 2487 | G15: 1232 | H15: 830 | I15: 817 | J15: 116 | K15: 2371 | L15: 56 | M15: 1176 | N15: 0 | O15: 830 | Q15: 2 | R15: 0.002446 | S15: 15 | T15: 2680 | U15: 2826 | V15: 2487 | W15: 1232 | X15: 830 | Y15: 817 | Z15: 116 | AA15: 2371 | AB15: 56 | AC15: 1176 | AD15: 0 | AE15: 830
A16: 3 | B16: 0.002081 | C16: 25 | D16: 2647 | E16: 2818 | F16: 2465 | G16: 1246 | H16: 824 | I16: 839 | J16: 108 | K16: 2357 | L16: 52 | M16: 1194 | N16: 0 | O16: 824 | Q16: 3 | R16: 0.002019 | S16: 15 | T16: 2647 | U16: 2818 | V16: 2465 | W16: 1246 | X16: 824 | Y16: 839 | Z16: 108 | AA16: 2357 | AB16: 52 | AC16: 1194 | AD16: 0 | AE16: 824
A17: 4 | B17: 0.001865 | C17: 24 | D17: 2730 | E17: 2885 | F17: 2435 | G17: 1248 | H17: 812 | I17: 812 | J17: 110 | K17: 2325 | L17: 40 | M17: 1208 | N17: 0 | O17: 812 | Q17: 4 | R17: 0.001994 | S17: 15 | T17: 2730 | U17: 2885 | V17: 2435 | W17: 1248 | X17: 812 | Y17: 812 | Z17: 110 | AA17: 2325 | AB17: 40 | AC17: 1208 | AD17: 0 | AE17: 812
A18: 5 | B18: 0.002107 | C18: 25 | D18: 2701 | E18: 2860 | F18: 2426 | G18: 1275 | H18: 825 | I18: 806 | J18: 93 | K18: 2333 | L18: 49 | M18: 1226 | N18: 0 | O18: 825 | Q18: 5 | R18: 0.002106 | S18: 14 | T18: 2701 | U18: 2860 | V18: 2426 | W18: 1275 | X18: 825 | Y18: 806 | Z18: 93 | AA18: 2333 | AB18: 49 | AC18: 1226 | AD18: 0 | AE18: 825
A19: 6 | B19: 0.002003 | C19: 25 | D19: 2685 | E19: 2840 | F19: 2569 | G19: 1203 | H19: 736 | I19: 844 | J19: 105 | K19: 2464 | L19: 44 | M19: 1159 | N19: 0 | O19: 736 | Q19: 6 | R19: 0.002357 | S19: 15 | T19: 2685 | U19: 2840 | V19: 2569 | W19: 1203 | X19: 736 | Y19: 844 | Z19: 105 | AA19: 2464 | AB19: 44 | AC19: 1159 | AD19: 0 | AE19: 736
A20: 7 | B20: 0.002112 | C20: 22 | D20: 2630 | E20: 2794 | F20: 2447 | G20: 1243 | H20: 829 | I20: 879 | J20: 98 | K20: 2349 | L20: 61 | M20: 1182 | N20: 1 | O20: 828 | Q20: 7 | R20: 0.002191 | S20: 15 | T20: 2630 | U20: 2794 | V20: 2447 | W20: 1243 | X20: 829 | Y20: 879 | Z20: 98 | AA20: 2349 | AB20: 61 | AC20: 1182 | AD20: 1 | AE20: 828
A21: 8 | B21: 0.002222 | C21: 24 | D21: 2739 | E21: 2906 | F21: 2483 | G21: 1223 | H21: 759 | I21: 821 | J21: 111 | K21: 2372 | L21: 42 | M21: 1181 | N21: 0 | O21: 759 | Q21: 8 | R21: 0.002184 | S21: 15 | T21: 2739 | U21: 2906 | V21: 2483 | W21: 1223 | X21: 759 | Y21: 821 | Z21: 111 | AA21: 2372 | AB21: 42 | AC21: 1181 | AD21: 0 | AE21: 759
A22: 9 | B22: 0.00207 | C22: 24 | D22: 2664 | E22: 2820 | F22: 2445 | G22: 1248 | H22: 817 | I22: 862 | J22: 98 | K22: 2347 | L22: 53 | M22: 1195 | N22: 1 | O22: 816 | Q22: 9 | R22: 0.002456 | S22: 14 | T22: 2664 | U22: 2820 | V22: 2445 | W22: 1248 | X22: 817 | Y22: 862 | Z22: 98 | AA22: 2347 | AB22: 53 | AC22: 1195 | AD22: 1 | AE22: 816
A23: 10 | B23: 0.002433 | C23: 27 | D23: 2714 | E23: 2880 | F23: 2445 | G23: 1265 | H23: 787 | I23: 815 | J23: 91 | K23: 2354 | L23: 60 | M23: 1205 | N23: 0 | O23: 787 | Q23: 10 | R23: 0.002126 | S23: 15 | T23: 2714 | U23: 2880 | V23: 2445 | W23: 1265 | X23: 787 | Y23: 815 | Z23: 91 | AA23: 2354 | AB23: 60 | AC23: 1205 | AD23: 0 | AE23: 787
A24: 11 | B24: 0.001951 | C24: 23 | D24: 2744 | E24: 2895 | F24: 2462 | G24: 1279 | H24: 772 | I24: 784 | J24: 99 | K24: 2363 | L24: 52 | M24: 1227 | N24: 0 | O24: 772 | Q24: 11 | R24: 0.002067 | S24: 15 | T24: 2744 | U24: 2895 | V24: 2462 | W24: 1279 | X24: 772 | Y24: 784 | Z24: 99 | AA24: 2363 | AB24: 52 | AC24: 1227 | AD24: 0 | AE24: 772
A25: 12 | B25: 0.002167 | C25: 24 | D25: 2784 | E25: 2950 | F25: 2396 | G25: 1188 | H25: 816 | I25: 842 | J25: 103 | K25: 2293 | L25: 42 | M25: 1146 | N25: 0 | O25: 816 | Q25: 12 | R25: 0.002126 | S25: 15 | T25: 2784 | U25: 2950 | V25: 2396 | W25: 1188 | X25: 816 | Y25: 842 | Z25: 103 | AA25: 2293 | AB25: 42 | AC25: 1146 | AD25: 0 | AE25: 816
... A43: 30 | B43: 0.002073 | C43: 24 | D43: 2766 | E43: 2903 | F43: 2457 | G43: 1193 | H43: 835 | I43: 804 | J43: 114 | K43: 2343 | L43: 41 | M43: 1152 | N43: 0 | O43: 835 | Q43: 30 | R43: 0.00207 | S43: 14 | T43: 2766 | U43: 2903 | V43: 2457 | W43: 1193 | X43: 835 | Y43: 804 | Z43: 114 | AA43: 2343 | AB43: 41 | AC43: 1152 | AD43: 0 | AE43: 835

Sheet Inv_16384
A1: Resultados de Simulación para m = 16384
B3: Estadísticas de Tiempos y Alturas
B4: Métrica | C4: BST | D4: RedBlackBST
B5: Tiempo Mínimo (s) | C5: =MIN(B14:B43) -> 0 | D5: =MIN(R14:R43) -> 0
B6: Tiempo Máximo (s) | C6: =MAX(B14:B43) -> 0 | D6: =MAX(R14:R43) -> 0
B7: Tiempo Promedio (s) | C7: =AVERAGE(B14:B43) -> 0 | D7: =AVERAGE(R14:R43) -> 0
B8: Desviación Estándar (s) | C8: =STDEV.S(B14:B43) -> 0 | D8: =STDEV.S(R14:R43) -> 0
B9: Coeficiente de Variación | C9: =C7/C6 -> 0 | D9: =D7/D6 -> 0
B10: Altura Promedio | C10: =AVERAGE(C14:C43) -> 0 | D10: =AVERAGE(S14:S43) -> 0
B11: Altura Máxima | C11: =MAX(C14:C43) -> 0 | D11: =MAX(S14:S43) -> 0
A12: Microdatos de BST (30 Ejecuciones) | Q12: Microdatos de RedBlackBST (30 Ejecuciones)
A13: Instancia | B13: Tiempo (s) | C13: Altura Final | D13: Tamaño Final | E13: Compra Tot | F13: Cons Tot | G13: Prést Tot | H13: Dev Tot | I13: Baja Tot | J13: Cons Exit | K13: Cons Fall | L13: Prést Exit | M13: Prést Fall | N13: Dev Exit | O13: Dev Fall | Q13: Instancia | R13: Tiempo (s) | S13: Altura Final | T13: Tamaño Final | U13: Compra Tot | V13: Cons Tot | W13: Prést Tot | X13: Dev Tot | Y13: Baja Tot | Z13: Cons Exit | AA13: Cons Fall | AB13: Prést Exit | AC13: Prést Fall | AD13: Dev Exit | AE13: Dev Fall
A14: 1 | B14: 0.007275 | C14: 31 | D14: 5393 | E14: 5702 | F14: 4929 | G14: 2449 | H14: 1656 | I14: 1648 | J14: 213 | K14: 4716 | L14: 105 | M14: 2344 | N14: 0 | O14: 1656 | Q14: 1 | R14: 0.004831 | S14: 16 | T14: 5393 | U14: 5702 | V14: 4929 | W14: 2449 | X14: 1656 | Y14: 1648 | Z14: 213 | AA14: 4716 | AB14: 105 | AC14: 2344 | AD14: 0 | AE14: 1656
A15: 2 | B15: 0.004362 | C15: 31 | D15: 5440 | E15: 5753 | F15: 4810 | G15: 2540 | H15: 1600 | I15: 1681 | J15: 220 | K15: 4590 | L15: 97 | M15: 2443 | N15: 1 | O15: 1599 | Q15: 2 | R15: 0.004336 | S15: 16 | T15: 5440 | U15: 5753 | V15: 4810 | W15: 2540 | X15: 1600 | Y15: 1681 | Z15: 220 | AA15: 4590 | AB15: 97 | AC15: 2443 | AD15: 1 | AE15: 1599
A16: 3 | B16: 0.0048 | C16: 29 | D16: 5448 | E16: 5764 | F16: 4866 | G16: 2374 | H16: 1685 | I16: 1695 | J16: 201 | K16: 4665 | L16: 98 | M16: 2276 | N16: 0 | O16: 1685 | Q16: 3 | R16: 0.004214 | S16: 16 | T16: 5448 | U16: 5764 | V16: 4866 | W16: 2374 | X16: 1685 | Y16: 1695 | Z16: 201 | AA16: 4665 | AB16: 98 | AC16: 2276 | AD16: 0 | AE16: 1685
A17: 4 | B17: 0.010346 | C17: 27 | D17: 5405 | E17: 5705 | F17: 4878 | G17: 2491 | H17: 1631 | I17: 1679 | J17: 183 | K17: 4695 | L17: 93 | M17: 2398 | N17: 0 | O17: 1631 | Q17: 4 | R17: 0.004088 | S17: 16 | T17: 5405 | U17: 5705 | V17: 4878 | W17: 2491 | X17: 1631 | Y17: 1679 | Z17: 183 | AA17: 4695 | AB17: 93 | AC17: 2398 | AD17: 0 | AE17: 1631
A18: 5 | B18: 0.01025 | C18: 29 | D18: 5334 | E18: 5609 | F18: 4965 | G18: 2484 | H18: 1653 | I18: 1673 | J18: 216 | K18: 4749 | L18: 92 | M18: 2392 | N18: 0 | O18: 1653 | Q18: 5 | R18: 0.009748 | S18: 17 | T18: 5334 | U18: 5609 | V18: 4965 | W18: 2484 | X18: 1653 | Y18: 1673 | Z18: 216 | AA18: 4749 | AB18: 92 | AC18: 2392 | AD18: 0 | AE18: 1653
A19: 6 | B19: 0.009535 | C19: 28 | D19: 5430 | E19: 5737 | F19: 4948 | G19: 2411 | H19: 1635 | I19: 1653 | J19: 216 | K19: 4732 | L19: 94 | M19: 2317 | N19: 1 | O19: 1634 | Q19: 6 | R19: 0.010112 | S19: 16 | T19: 5430 | U19: 5737 | V19: 4948 | W19: 2411 | X19: 1635 | Y19: 1653 | Z19: 216 | AA19: 4732 | AB19: 94 | AC19: 2317 | AD19: 1 | AE19: 1634
A20: 7 | B20: 0.009938 | C20: 26 | D20: 5561 | E20: 5861 | F20: 4799 | G20: 2436 | H20: 1636 | I20: 1652 | J20: 200 | K20: 4599 | L20: 78 | M20: 2358 | N20: 1 | O20: 1635 | Q20: 7 | R20: 0.00961 | S20: 15 | T20: 5561 | U20: 5861 | V20: 4799 | W20: 2436 | X20: 1636 | Y20: 1652 | Z20: 200 | AA20: 4599 | AB20: 78 | AC20: 2358 | AD20: 1 | AE20: 1635
A21: 8 | B21: 0.009793 | C21: 29 | D21: 5503 | E21: 5793 | F21: 4846 | G21: 2431 | H21: 1638 | I21: 1676 | J21: 217 | K21: 4629 | L21: 89 | M21: 2342 | N21: 1 | O21: 1637 | Q21: 8 | R21: 0.007914 | S21: 16 | T21: 5503 | U21: 5793 | V21: 4846 | W21: 2431 | X21: 1638 | Y21: 1676 | Z21: 217 | AA21: 4629 | AB21: 89 | AC21: 2342 | AD21: 1 | AE21: 1637
A22: 9 | B22: 0.004771 | C22: 27 | D22: 5454 | E22: 5736 | F22: 4904 | G22: 2494 | H22: 1662 | I22: 1588 | J22: 221 | K22: 4683 | L22: 90 | M22: 2404 | N22: 0 | O22: 1662 | Q22: 9 | R22: 0.004294 | S22: 16 | T22: 5454 | U22: 5736 | V22: 4904 | W22: 2494 | X22: 1662 | Y22: 1588 | Z22: 221 | AA22: 4683 | AB22: 90 | AC22: 2404 | AD22: 0 | AE22: 1662
A23: 10 | B23: 0.004339 | C23: 25 | D23: 5447 | E23: 5767 | F23: 4888 | G23: 2473 | H23: 1696 | I23: 1560 | J23: 207 | K23: 4681 | L23: 98 | M23: 2375 | N23: 0 | O23: 1696 | Q23: 10 | R23: 0.004203 | S23: 16 | T23: 5447 | U23: 5767 | V23: 4888 | W23: 2473 | X23: 1696 | Y23: 1560 | Z23: 207 | AA23: 4681 | AB23: 98 | AC23: 2375 | AD23: 0 | AE23: 1696
A24: 11 | B24: 0.004207 | C24: 25 | D24: 5444 | E24: 5753 | F24: 4954 | G24: 2499 | H24: 1620 | I24: 1558 | J24: 211 | K24: 4743 | L24: 92 | M24: 2407 | N24: 0 | O24: 1620 | Q24: 11 | R24: 0.004271 | S24: 15 | T24: 5444 | U24: 5753 | V24: 4954 | W24: 2499 | X24: 1620 | Y24: 1558 | Z24: 211 | AA24: 4743 | AB24: 92 | AC24: 2407 | AD24: 0 | AE24: 1620
A25: 12 | B25: 0.004672 | C25: 30 | D25: 5404 | E25: 5696 | F25: 4880 | G25: 2503 | H25: 1640 | I25: 1665 | J25: 219 | K25: 4661 | L25: 98 | M25: 2405 | N25: 1 | O25: 1639 | Q25: 12 | R25: 0.004331 | S25: 16 | T25: 5404 | U25: 5696 | V25: 4880 | W25: 2503 | X25: 1640 | Y25: 1665 | Z25: 219 | AA25: 4661 | AB25: 98 | AC25: 2405 | AD25: 1 | AE25: 1639
... A43: 30 | B43: 0.002672 | C43: 26 | D43: 5359 | E43: 5669 | F43: 4915 | G43: 2506 | H43: 1660 | I43: 1634 | J43: 198 | K43: 4717 | L43: 111 | M43: 2395 | N43: 0 | O43: 1660 | Q43: 30 | R43: 0.002592 | S43: 17 | T43: 5359 | U43: 5669 | V43: 4915 | W43: 2506 | X43: 1660 | Y43: 1634 | Z43: 198 | AA43: 4717 | AB43: 111 | AC43: 2395 | AD43: 0 | AE43: 1660

Sheet Inv_32768
A1: Resultados de Simulación para m = 32768
B3: Estadísticas de Tiempos y Alturas
B4: Métrica | C4: BST | D4: RedBlackBST
B5: Tiempo Mínimo (s) | C5: =MIN(B14:B43) -> 0 | D5: =MIN(R14:R43) -> 0
B6: Tiempo Máximo (s) | C6: =MAX(B14:B43) -> 0 | D6: =MAX(R14:R43) -> 0
B7: Tiempo Promedio (s) | C7: =AVERAGE(B14:B43) -> 0 | D7: =AVERAGE(R14:R43) -> 0
B8: Desviación Estándar (s) | C8: =STDEV.S(B14:B43) -> 0 | D8: =STDEV.S(R14:R43) -> 0
B9: Coeficiente de Variación | C9: =C7/C6 -> 0 | D9: =D7/D6 -> 0
B10: Altura Promedio | C10: =AVERAGE(C14:C43) -> 0 | D10: =AVERAGE(S14:S43) -> 0
B11: Altura Máxima | C11: =MAX(C14:C43) -> 0 | D11: =MAX(S14:S43) -> 0
A12: Microdatos de BST (30 Ejecuciones) | Q12: Microdatos de RedBlackBST (30 Ejecuciones)
A13: Instancia | B13: Tiempo (s) | C13: Altura Final | D13: Tamaño Final | E13: Compra Tot | F13: Cons Tot | G13: Prést Tot | H13: Dev Tot | I13: Baja Tot | J13: Cons Exit | K13: Cons Fall | L13: Prést Exit | M13: Prést Fall | N13: Dev Exit | O13: Dev Fall | Q13: Instancia | R13: Tiempo (s) | S13: Altura Final | T13: Tamaño Final | U13: Compra Tot | V13: Cons Tot | W13: Prést Tot | X13: Dev Tot | Y13: Baja Tot | Z13: Cons Exit | AA13: Cons Fall | AB13: Prést Exit | AC13: Prést Fall | AD13: Dev Exit | AE13: Dev Fall
A14: 1 | B14: 0.00939 | C14: 29 | D14: 10878 | E14: 11525 | F14: 9770 | G14: 4998 | H14: 3237 | I14: 3238 | J14: 395 | K14: 9375 | L14: 203 | M14: 4795 | N14: 0 | O14: 3237 | Q14: 1 | R14: 0.007756 | S14: 17 | T14: 10878 | U14: 11525 | V14: 9770 | W14: 4998 | X14: 3237 | Y14: 3238 | Z14: 395 | AA14: 9375 | AB14: 203 | AC14: 4795 | AD14: 0 | AE14: 3237
A15: 2 | B15: 0.006234 | C15: 28 | D15: 10737 | E15: 11362 | F15: 9894 | G15: 4826 | H15: 3313 | I15: 3373 | J15: 437 | K15: 9457 | L15: 202 | M15: 4624 | N15: 2 | O15: 3311 | Q15: 2 | R15: 0.007515 | S15: 17 | T15: 10737 | U15: 11362 | V15: 9894 | W15: 4826 | X15: 3313 | Y15: 3373 | Z15: 437 | AA15: 9457 | AB15: 202 | AC15: 4624 | AD15: 2 | AE15: 3311
A16: 3 | B16: 0.009934 | C16: 30 | D16: 10843 | E16: 11469 | F16: 9849 | G16: 4893 | H16: 3258 | I16: 3299 | J16: 415 | K16: 9434 | L16: 201 | M16: 4692 | N16: 1 | O16: 3257 | Q16: 3 | R16: 0.006113 | S16: 17 | T16: 10843 | U16: 11469 | V16: 9849 | W16: 4893 | X16: 3258 | Y16: 3299 | Z16: 415 | AA16: 9434 | AB16: 201 | AC16: 4692 | AD16: 1 | AE16: 3257
A17: 4 | B17: 0.007198 | C17: 32 | D17: 10747 | E17: 11353 | F17: 9888 | G17: 4923 | H17: 3282 | I17: 3322 | J17: 431 | K17: 9457 | L17: 180 | M17: 4743 | N17: 2 | O17: 3280 | Q17: 4 | R17: 0.006919 | S17: 17 | T17: 10747 | U17: 11353 | V17: 9888 | W17: 4923 | X17: 3282 | Y17: 3322 | Z17: 431 | AA17: 9457 | AB17: 180 | AC17: 4743 | AD17: 2 | AE17: 3280
A18: 5 | B18: 0.007362 | C18: 31 | D18: 10665 | E18: 11314 | F18: 10062 | G18: 4795 | H18: 3252 | I18: 3345 | J18: 419 | K18: 9643 | L18: 179 | M18: 4616 | N18: 2 | O18: 3250 | Q18: 5 | R18: 0.006877 | S18: 18 | T18: 10665 | U18: 11314 | V18: 10062 | W18: 4795 | X18: 3252 | Y18: 3345 | Z18: 419 | AA18: 9643 | AB18: 179 | AC18: 4616 | AD18: 2 | AE18: 3250
A19: 6 | B19: 0.006568 | C19: 27 | D19: 10800 | E19: 11432 | F19: 9838 | G19: 4964 | H19: 3274 | I19: 3260 | J19: 431 | K19: 9407 | L19: 171 | M19: 4793 | N19: 0 | O19: 3274 | Q19: 6 | R19: 0.006386 | S19: 17 | T19: 10800 | U19: 11432 | V19: 9838 | W19: 4964 | X19: 3274 | Y19: 3260 | Z19: 431 | AA19: 9407 | AB19: 171 | AC19: 4793 | AD19: 0 | AE19: 3274
A20: 7 | B20: 0.009553 | C20: 29 | D20: 10942 | E20: 11571 | F20: 9864 | G20: 4820 | H20: 3190 | I20: 3323 | J20: 406 | K20: 9458 | L20: 199 | M20: 4621 | N20: 2 | O20: 3188 | Q20: 7 | R20: 0.009251 | S20: 18 | T20: 10942 | U20: 11571 | V20: 9864 | W20: 4820 | X20: 3190 | Y20: 3323 | Z20: 406 | AA20: 9458 | AB20: 199 | AC20: 4621 | AD20: 2 | AE20: 3188
A21: 8 | B21: 0.006718 | C21: 28 | D21: 10751 | E21: 11335 | F21: 9789 | G21: 4957 | H21: 3343 | I21: 3344 | J21: 405 | K21: 9384 | L21: 183 | M21: 4774 | N21: 2 | O21: 3341 | Q21: 8 | R21: 0.006119 | S21: 18 | T21: 10751 | U21: 11335 | V21: 9789 | W21: 4957 | X21: 3343 | Y21: 3344 | Z21: 405 | AA21: 9384 | AB21: 183 | AC21: 4774 | AD21: 2 | AE21: 3341
A22: 9 | B22: 0.008262 | C22: 27 | D22: 10852 | E22: 11461 | F22: 9809 | G22: 4864 | H22: 3319 | I22: 3315 | J22: 393 | K22: 9416 | L22: 175 | M22: 4689 | N22: 1 | O22: 3318 | Q22: 9 | R22: 0.007399 | S22: 17 | T22: 10852 | U22: 11461 | V22: 9809 | W22: 4864 | X22: 3319 | Y22: 3315 | Z22: 393 | AA22: 9416 | AB22: 175 | AC22: 4689 | AD22: 1 | AE22: 3318
A23: 10 | B23: 0.006558 | C23: 30 | D23: 10898 | E23: 11515 | F23: 9871 | G23: 4892 | H23: 3249 | I23: 3241 | J23: 416 | K23: 9455 | L23: 189 | M23: 4703 | N23: 3 | O23: 3246 | Q23: 10 | R23: 0.007569 | S23: 18 | T23: 10898 | U23: 11515 | V23: 9871 | W23: 4892 | X23: 3249 | Y23: 3241 | Z23: 416 | AA23: 9455 | AB23: 189 | AC23: 4703 | AD23: 3 | AE23: 3246
A24: 11 | B24: 0.006713 | C24: 32 | D24: 10805 | E24: 11413 | F24: 9858 | G24: 4864 | H24: 3283 | I24: 3350 | J24: 405 | K24: 9453 | L24: 179 | M24: 4685 | N24: 0 | O24: 3283 | Q24: 11 | R24: 0.00767 | S24: 17 | T24: 10805 | U24: 11413 | V24: 9858 | W24: 4864 | X24: 3283 | Y24: 3350 | Z24: 405 | AA24: 9453 | AB24: 179 | AC24: 4685 | AD24: 0 | AE24: 3283
A25: 12 | B25: 0.008882 | C25: 31 | D25: 10837 | E25: 11459 | F25: 9781 | G25: 4951 | H25: 3341 | I25: 3236 | J25: 411 | K25: 9370 | L25: 180 | M25: 4771 | N25: 4 | O25: 3337 | Q25: 12 | R25: 0.009394 | S25: 19 | T25: 10837 | U25: 11459 | V25: 9781 | W25: 4951 | X25: 3341 | Y25: 3236 | Z25: 411 | AA25: 9370 | AB25: 180 | AC25: 4771 | AD25: 4 | AE25: 3337
... A43: 30 | B43: 0.006389 | C43: 32 | D43: 10677 | E43: 11313 | F43: 9975 | G43: 4925 | H43: 3275 | I43: 3280 | J43: 418 | K43: 9557 | L43: 190 | M43: 4735 | N43: 1 | O43: 3274 | Q43: 30 | R43: 0.006045 | S43: 18 | T43: 10677 | U43: 11313 | V43: 9975 | W43: 4925 | X43: 3275 | Y43: 3280 | Z43: 418 | AA43: 9557 | AB43: 190 | AC43: 4735 | AD43: 1 | AE43: 3274

Sheet Inv_65536
A1: Resultados de Simulación para m = 65536
B3: Estadísticas de Tiempos y Alturas
B4: Métrica | C4: BST | D4: RedBlackBST
B5: Tiempo Mínimo (s) | C5: =MIN(B14:B43) -> 0 | D5: =MIN(R14:R43) -> 0
B6: Tiempo Máximo (s) | C6: =MAX(B14:B43) -> 0 | D6: =MAX(R14:R43) -> 0
B7: Tiempo Promedio (s) | C7: =AVERAGE(B14:B43) -> 0 | D7: =AVERAGE(R14:R43) -> 0
B8: Desviación Estándar (s) | C8: =STDEV.S(B14:B43) -> 0 | D8: =STDEV.S(R14:R43) -> 0
B9: Coeficiente de Variación | C9: =C7/C6 -> 0 | D9: =D7/D6 -> 0
B10: Altura Promedio | C10: =AVERAGE(C14:C43) -> 0 | D10: =AVERAGE(S14:S43) -> 0
B11: Altura Máxima | C11: =MAX(C14:C43) -> 0 | D11: =MAX(S14:S43) -> 0
A12: Microdatos de BST (30 Ejecuciones) | Q12: Microdatos de RedBlackBST (30 Ejecuciones)
A13: Instancia | B13: Tiempo (s) | C13: Altura Final | D13: Tamaño Final | E13: Compra Tot | F13: Cons Tot | G13: Prést Tot | H13: Dev Tot | I13: Baja Tot | J13: Cons Exit | K13: Cons Fall | L13: Prést Exit | M13: Prést Fall | N13: Dev Exit | O13: Dev Fall | Q13: Instancia | R13: Tiempo (s) | S13: Altura Final | T13: Tamaño Final | U13: Compra Tot | V13: Cons Tot | W13: Prést Tot | X13: Dev Tot | Y13: Baja Tot | Z13: Cons Exit | AA13: Cons Fall | AB13: Prést Exit | AC13: Prést Fall | AD13: Dev Exit | AE13: Dev Fall
A14: 1 | B14: 0.015432 | C14: 31 | D14: 21728 | E14: 22978 | F14: 19799 | G14: 9685 | H14: 6583 | I14: 6491 | J14: 828 | K14: 18971 | L14: 365 | M14: 9320 | N14: 2 | O14: 6581 | Q14: 1 | R14: 0.014363 | S14: 20 | T14: 21728 | U14: 22978 | V14: 19799 | W14: 9685 | X14: 6583 | Y14: 6491 | Z14: 828 | AA14: 18971 | AB14: 365 | AC14: 9320 | AD14: 2 | AE14: 6581
A15: 2 | B15: 0.020562 | C15: 33 | D15: 21681 | E15: 22926 | F15: 19794 | G15: 9813 | H15: 6495 | I15: 6508 | J15: 807 | K15: 18987 | L15: 381 | M15: 9432 | N15: 3 | O15: 6492 | Q15: 2 | R15: 0.015101 | S15: 19 | T15: 21681 | U15: 22926 | V15: 19794 | W15: 9813 | X15: 6495 | Y15: 6508 | Z15: 807 | AA15: 18987 | AB15: 381 | AC15: 9432 | AD15: 3 | AE15: 6492
A16: 3 | B16: 0.015023 | C16: 34 | D16: 21679 | E16: 22904 | F16: 19811 | G16: 9767 | H16: 6560 | I16: 6494 | J16: 850 | K16: 18961 | L16: 343 | M16: 9424 | N16: 2 | O16: 6558 | Q16: 3 | R16: 0.015596 | S16: 20 | T16: 21679 | U16: 22904 | V16: 19811 | W16: 9767 | X16: 6560 | Y16: 6494 | Z16: 850 | AA16: 18961 | AB16: 343 | AC16: 9424 | AD16: 2 | AE16: 6558
A17: 4 | B17: 0.020071 | C17: 31 | D17: 21499 | E17: 22757 | F17: 19674 | G17: 9961 | H17: 6657 | I17: 6487 | J17: 829 | K17: 18845 | L17: 381 | M17: 9580 | N17: 0 | O17: 6657 | Q17: 4 | R17: 0.01463 | S17: 19 | T17: 21499 | U17: 22757 | V17: 19674 | W17: 9961 | X17: 6657 | Y17: 6487 | Z17: 829 | AA17: 18845 | AB17: 381 | AC17: 9580 | AD17: 0 | AE17: 6657
A18: 5 | B18: 0.01733 | C18: 34 | D18: 21685 | E18: 22956 | F18: 19518 | G18: 9822 | H18: 6606 | I18: 6634 | J18: 888 | K18: 18630 | L18: 381 | M18: 9441 | N18: 1 | O18: 6605 | Q18: 5 | R18: 0.016878 | S18: 19 | T18: 21685 | U18: 22956 | V18: 19518 | W18: 9822 | X18: 6606 | Y18: 6634 | Z18: 888 | AA18: 18630 | AB18: 381 | AC18: 9441 | AD18: 1 | AE18: 6605
A19: 6 | B19: 0.025486 | C19: 31 | D19: 21757 | E19: 22957 | F19: 19704 | G19: 9839 | H19: 6488 | I19: 6548 | J19: 780 | K19: 18924 | L19: 380 | M19: 9459 | N19: 2 | O19: 6486 | Q19: 6 | R19: 0.02174 | S19: 19 | T19: 21757 | U19: 22957 | V19: 19704 | W19: 9839 | X19: 6488 | Y19: 6548 | Z19: 780 | AA19: 18924 | AB19: 380 | AC19: 9459 | AD19: 2 | AE19: 6486
A20: 7 | B20: 0.026743 | C20: 32 | D20: 21730 | E20: 22970 | F20: 19577 | G20: 9863 | H20: 6631 | I20: 6495 | J20: 846 | K20: 18731 | L20: 402 | M20: 9461 | N20: 1 | O20: 6630 | Q20: 7 | R20: 0.023 | S20: 19 | T20: 21730 | U20: 22970 | V20: 19577 | W20: 9863 | X20: 6631 | Y20: 6495 | Z20: 846 | AA20: 18731 | AB20: 402 | AC20: 9461 | AD20: 1 | AE20: 6630
A21: 8 | B21: 0.027445 | C21: 37 | D21: 21545 | E21: 22771 | F21: 19613 | G21: 9827 | H21: 6550 | I21: 6775 | J21: 866 | K21: 18747 | L21: 385 | M21: 9442 | N21: 2 | O21: 6548 | Q21: 8 | R21: 0.023751 | S21: 19 | T21: 21545 | U21: 22771 | V21: 19613 | W21: 9827 | X21: 6550 | Y21: 6775 | Z21: 866 | AA21: 18747 | AB21: 385 | AC21: 9442 | AD21: 2 | AE21: 6548
A22: 9 | B22: 0.026184 | C22: 34 | D22: 21821 | E22: 23112 | F22: 19542 | G22: 9785 | H22: 6540 | I22: 6557 | J22: 849 | K22: 18693 | L22: 343 | M22: 9442 | N22: 1 | O22: 6539 | Q22: 9 | R22: 0.01743 | S22: 19 | T22: 21821 | U22: 23112 | V22: 19542 | W22: 9785 | X22: 6540 | Y22: 6557 | Z22: 849 | AA22: 18693 | AB22: 343 | AC22: 9442 | AD22: 1 | AE22: 6539
A23: 10 | B23: 0.019428 | C23: 30 | D23: 21570 | E23: 22774 | F23: 19832 | G23: 9804 | H23: 6656 | I23: 6470 | J23: 772 | K23: 19060 | L23: 358 | M23: 9446 | N23: 1 | O23: 6655 | Q23: 10 | R23: 0.022118 | S23: 19 | T23: 21570 | U23: 22774 | V23: 19832 | W23: 9804 | X23: 6656 | Y23: 6470 | Z23: 772 | AA23: 19060 | AB23: 358 | AC23: 9446 | AD23: 1 | AE23: 6655
A24: 11 | B24: 0.017953 | C24: 30 | D24: 21617 | E24: 22825 | F24: 19535 | G24: 9854 | H24: 6731 | I24: 6591 | J24: 855 | K24: 18680 | L24: 381 | M24: 9473 | N24: 1 | O24: 6730 | Q24: 11 | R24: 0.01834 | S24: 19 | T24: 21617 | U24: 22825 | V24: 19535 | W24: 9854 | X24: 6731 | Y24: 6591 | Z24: 855 | AA24: 18680 | AB24: 381 | AC24: 9473 | AD24: 1 | AE24: 6730
A25: 12 | B25: 0.019604 | C25: 35 | D25: 21649 | E25: 22872 | F25: 19506 | G25: 9913 | H25: 6634 | I25: 6611 | J25: 820 | K25: 18686 | L25: 352 | M25: 9561 | N25: 1 | O25: 6633 | Q25: 12 | R25: 0.016639 | S25: 19 | T25: 21649 | U25: 22872 | V25: 19506 | W25: 9913 | X25: 6634 | Y25: 6611 | Z25: 820 | AA25: 18686 | AB25: 352 | AC25: 9561 | AD25: 1 | AE25: 6633
... A43: 30 | B43: 0.015505 | C43: 35 | D43: 21647 | E43: 22913 | F43: 19692 | G43: 9829 | H43: 6574 | I43: 6528 | J43: 790 | K43: 18902 | L43: 371 | M43: 9458 | N43: 1 | O43: 6573 | Q43: 30 | R43: 0.017345 | S43: 19 | T43: 21647 | U43: 22913 | V43: 19692 | W43: 9829 | X43: 6574 | Y43: 6528 | Z43: 790 | AA43: 18902 | AB43: 371 | AC43: 9458 | AD43: 1 | AE43: 6573

Sheet Inv_131072
A1: Resultados de Simulación para m = 131072
B3: Estadísticas de Tiempos y Alturas
B4: Métrica | C4: BST | D4: RedBlackBST
B5: Tiempo Mínimo (s) | C5: =MIN(B14:B43) -> 0 | D5: =MIN(R14:R43) -> 0
B6: Tiempo Máximo (s) | C6: =MAX(B14:B43) -> 0 | D6: =MAX(R14:R43) -> 0
B7: Tiempo Promedio (s) | C7: =AVERAGE(B14:B43) -> 0 | D7: =AVERAGE(R14:R43) -> 0
B8: Desviación Estándar (s) | C8: =STDEV.S(B14:B43) -> 0 | D8: =STDEV.S(R14:R43) -> 0
B9: Coeficiente de Variación | C9: =C7/C6 -> 0 | D9: =D7/D6 -> 0
B10: Altura Promedio | C10: =AVERAGE(C14:C43) -> 0 | D10: =AVERAGE(S14:S43) -> 0
B11: Altura Máxima | C11: =MAX(C14:C43) -> 0 | D11: =MAX(S14:S43) -> 0
A12: Microdatos de BST (30 Ejecuciones) | Q12: Microdatos de RedBlackBST (30 Ejecuciones)
A13: Instancia | B13: Tiempo (s) | C13: Altura Final | D13: Tamaño Final | E13: Compra Tot | F13: Cons Tot | G13: Prést Tot | H13: Dev Tot | I13: Baja Tot | J13: Cons Exit | K13: Cons Fall | L13: Prést Exit | M13: Prést Fall | N13: Dev Exit | O13: Dev Fall | Q13: Instancia | R13: Tiempo (s) | S13: Altura Final | T13: Tamaño Final | U13: Compra Tot | V13: Cons Tot | W13: Prést Tot | X13: Dev Tot | Y13: Baja Tot | Z13: Cons Exit | AA13: Cons Fall | AB13: Prést Exit | AC13: Prést Fall | AD13: Dev Exit | AE13: Dev Fall
A14: 1 | B14: 0.054601 | C14: 36 | D14: 43224 | E14: 45766 | F14: 39294 | G14: 19731 | H14: 13170 | I14: 13111 | J14: 1619 | K14: 37675 | L14: 730 | M14: 19001 | N14: 4 | O14: 13166 | Q14: 1 | R14: 0.048437 | S14: 20 | T14: 43224 | U14: 45766 | V14: 39294 | W14: 19731 | X14: 13170 | Y14: 13111 | Z14: 1619 | AA14: 37675 | AB14: 730 | AC14: 19001 | AD14: 4 | AE14: 13166
A15: 2 | B15: 0.04903 | C15: 39 | D15: 43121 | E15: 45544 | F15: 39524 | G15: 19818 | H15: 13081 | I15: 13105 | J15: 1661 | K15: 37863 | L15: 769 | M15: 19049 | N15: 2 | O15: 13079 | Q15: 2 | R15: 0.038465 | S15: 21 | T15: 43121 | U15: 45544 | V15: 39524 | W15: 19818 | X15: 13081 | Y15: 13105 | Z15: 1661 | AA15: 37863 | AB15: 769 | AC15: 19049 | AD15: 2 | AE15: 13079
A16: 3 | B16: 0.045365 | C16: 32 | D16: 43299 | E16: 45801 | F16: 39342 | G16: 19569 | H16: 13063 | I16: 13297 | J16: 1677 | K16: 37665 | L16: 735 | M16: 18834 | N16: 2 | O16: 13061 | Q16: 3 | R16: 0.040405 | S16: 20 | T16: 43299 | U16: 45801 | V16: 39342 | W16: 19569 | X16: 13063 | Y16: 13297 | Z16: 1677 | AA16: 37665 | AB16: 735 | AC16: 18834 | AD16: 2 | AE16: 13061
A17: 4 | B17: 0.039429 | C17: 34 | D17: 43342 | E17: 45798 | F17: 39414 | G17: 19601 | H17: 13195 | I17: 13064 | J17: 1659 | K17: 37755 | L17: 727 | M17: 18874 | N17: 4 | O17: 13191 | Q17: 4 | R17: 0.03656 | S17: 21 | T17: 43342 | U17: 45798 | V17: 39414 | W17: 19601 | X17: 13195 | Y17: 13064 | Z17: 1659 | AA17: 37755 | AB17: 727 | AC17: 18874 | AD17: 4 | AE17: 13191
A18: 5 | B18: 0.037479 | C18: 36 | D18: 43236 | E18: 45728 | F18: 39490 | G18: 19631 | H18: 12975 | I18: 13248 | J18: 1623 | K18: 37867 | L18: 745 | M18: 18886 | N18: 4 | O18: 12971 | Q18: 5 | R18: 0.036462 | S18: 21 | T18: 43236 | U18: 45728 | V18: 39490 | W18: 19631 | X18: 12975 | Y18: 13248 | Z18: 1623 | AA18: 37867 | AB18: 745 | AC18: 18886 | AD18: 4 | AE18: 12971
A19: 6 | B19: 0.039254 | C19: 36 | D19: 43503 | E19: 45919 | F19: 39443 | G19: 19500 | H19: 13034 | I19: 13176 | J19: 1606 | K19: 37837 | L19: 823 | M19: 18677 | N19: 1 | O19: 13033 | Q19: 6 | R19: 0.038638 | S19: 21 | T19: 43503 | U19: 45919 | V19: 39443 | W19: 19500 | X19: 13034 | Y19: 13176 | Z19: 1606 | AA19: 37837 | AB19: 823 | AC19: 18677 | AD19: 1 | AE19: 13033
A20: 7 | B20: 0.038011 | C20: 40 | D20: 43284 | E20: 45721 | F20: 39467 | G20: 19608 | H20: 13021 | I20: 13255 | J20: 1628 | K20: 37839 | L20: 757 | M20: 18851 | N20: 5 | O20: 13016 | Q20: 7 | R20: 0.040572 | S20: 21 | T20: 43284 | U20: 45721 | V20: 39467 | W20: 19608 | X20: 13021 | Y20: 13255 | Z20: 1628 | AA20: 37839 | AB20: 757 | AC20: 18851 | AD20: 5 | AE20: 13016
A21: 8 | B21: 0.063822 | C21: 36 | D21: 43354 | E21: 45817 | F21: 38953 | G21: 19733 | H21: 13284 | I21: 13285 | J21: 1706 | K21: 37247 | L21: 773 | M21: 18960 | N21: 5 | O21: 13279 | Q21: 8 | R21: 0.0607 | S21: 20 | T21: 43354 | U21: 45817 | V21: 38953 | W21: 19733 | X21: 13284 | Y21: 13285 | Z21: 1706 | AA21: 37247 | AB21: 773 | AC21: 18960 | AD21: 5 | AE21: 13279
A22: 9 | B22: 0.050112 | C22: 36 | D22: 43387 | E22: 45835 | F22: 39392 | G22: 19685 | H22: 13118 | I22: 13042 | J22: 1700 | K22: 37692 | L22: 812 | M22: 18873 | N22: 3 | O22: 13115 | Q22: 9 | R22: 0.046123 | S22: 20 | T22: 43387 | U22: 45835 | V22: 39392 | W22: 19685 | X22: 13118 | Y22: 13042 | Z22: 1700 | AA22: 37692 | AB22: 812 | AC22: 18873 | AD22: 3 | AE22: 13115
A23: 10 | B23: 0.051204 | C23: 36 | D23: 43510 | E23: 46022 | F23: 39114 | G23: 19478 | H23: 13206 | I23: 13252 | J23: 1579 | K23: 37535 | L23: 708 | M23: 18770 | N23: 4 | O23: 13202 | Q23: 10 | R23: 0.043915 | S23: 20 | T23: 43510 | U23: 46022 | V23: 39114 | W23: 19478 | X23: 13206 | Y23: 13252 | Z23: 1579 | AA23: 37535 | AB23: 708 | AC23: 18770 | AD23: 4 | AE23: 13202
A24: 11 | B24: 0.043538 | C24: 37 | D24: 43339 | E24: 45834 | F24: 39215 | G24: 19861 | H24: 13216 | I24: 12946 | J24: 1563 | K24: 37652 | L24: 728 | M24: 19133 | N24: 2 | O24: 13214 | Q24: 11 | R24: 0.043392 | S24: 20 | T24: 43339 | U24: 45834 | V24: 39215 | W24: 19861 | X24: 13216 | Y24: 12946 | Z24: 1563 | AA24: 37652 | AB24: 728 | AC24: 19133 | AD24: 2 | AE24: 13214
A25: 12 | B25: 0.043484 | C25: 33 | D25: 43670 | E25: 46132 | F25: 38975 | G25: 19834 | H25: 13134 | I25: 12997 | J25: 1676 | K25: 37299 | L25: 801 | M25: 19033 | N25: 7 | O25: 13127 | Q25: 12 | R25: 0.043431 | S25: 20 | T25: 43670 | U25: 46132 | V25: 38975 | W25: 19834 | X25: 13134 | Y25: 12997 | Z25: 1676 | AA25: 37299 | AB25: 801 | AC25: 19033 | AD25: 7 | AE25: 13127
... A43: 30 | B43: 0.045773 | C43: 37 | D43: 43331 | E43: 45807 | F43: 39238 | G43: 19594 | H43: 13252 | I43: 13181 | J43: 1649 | K43: 37589 | L43: 729 | M43: 18865 | N43: 0 | O43: 13252 | Q43: 30 | R43: 0.035523 | S43: 21 | T43: 43331 | U43: 45807 | V43: 39238 | W43: 19594 | X43: 13252 | Y43: 13181 | Z43: 1649 | AA43: 37589 | AB43: 729 | AC43: 18865 | AD43: 0 | AE43: 13252

Sheet Inv_262144
A1: Resultados de Simulación para m = 262144
B3: Estadísticas de Tiempos y Alturas
B4: Métrica | C4: BST | D4: RedBlackBST
B5: Tiempo Mínimo (s) | C5: =MIN(B14:B43) -> 0 | D5: =MIN(R14:R43) -> 0
B6: Tiempo Máximo (s) | C6: =MAX(B14:B43) -> 0 | D6: =MAX(R14:R43) -> 0
B7: Tiempo Promedio (s) | C7: =AVERAGE(B14:B43) -> 0 | D7: =AVERAGE(R14:R43) -> 0
B8: Desviación Estándar (s) | C8: =STDEV.S(B14:B43) -> 0 | D8: =STDEV.S(R14:R43) -> 0
B9: Coeficiente de Variación | C9: =C7/C6 -> 0 | D9: =D7/D6 -> 0
B10: Altura Promedio | C10: =AVERAGE(C14:C43) -> 0 | D10: =AVERAGE(S14:S43) -> 0
B11: Altura Máxima | C11: =MAX(C14:C43) -> 0 | D11: =MAX(S14:S43) -> 0
A12: Microdatos de BST (30 Ejecuciones) | Q12: Microdatos de RedBlackBST (30 Ejecuciones)
A13: Instancia | B13: Tiempo (s) | C13: Altura Final | D13: Tamaño Final | E13: Compra Tot | F13: Cons Tot | G13: Prést Tot | H13: Dev Tot | I13: Baja Tot | J13: Cons Exit | K13: Cons Fall | L13: Prést Exit | M13: Prést Fall | N13: Dev Exit | O13: Dev Fall | Q13: Instancia | R13: Tiempo (s) | S13: Altura Final | T13: Tamaño Final | U13: Compra Tot | V13: Cons Tot | W13: Prést Tot | X13: Dev Tot | Y13: Baja Tot | Z13: Cons Exit | AA13: Cons Fall | AB13: Prést Exit | AC13: Prést Fall | AD13: Dev Exit | AE13: Dev Fall
A14: 1 | B14: 0.099288 | C14: 39 | D14: 87138 | E14: 92151 | F14: 78543 | G14: 39193 | H14: 25932 | I14: 26325 | J14: 3263 | K14: 75280 | L14: 1519 | M14: 37674 | N14: 7 | O14: 25925 | Q14: 1 | R14: 0.085834 | S14: 22 | T14: 87138 | U14: 92151 | V14: 78543 | W14: 39193 | X14: 25932 | Y14: 26325 | Z14: 3263 | AA14: 75280 | AB14: 1519 | AC14: 37674 | AD14: 7 | AE14: 25925
A15: 2 | B15: 0.090941 | C15: 40 | D15: 86681 | E15: 91583 | F15: 79031 | G15: 39521 | H15: 26051 | I15: 25958 | J15: 3423 | K15: 75608 | L15: 1546 | M15: 37975 | N15: 7 | O15: 26044 | Q15: 2 | R15: 0.094687 | S15: 22 | T15: 86681 | U15: 91583 | V15: 79031 | W15: 39521 | X15: 26051 | Y15: 25958 | Z15: 3423 | AA15: 75608 | AB15: 1546 | AC15: 37975 | AD15: 7 | AE15: 26044
A16: 3 | B16: 0.115331 | C16: 39 | D16: 86934 | E16: 91930 | F16: 78687 | G16: 39141 | H16: 26355 | I16: 26031 | J16: 3332 | K16: 75355 | L16: 1555 | M16: 37586 | N16: 9 | O16: 26346 | Q16: 3 | R16: 0.093088 | S16: 22 | T16: 86934 | U16: 91930 | V16: 78687 | W16: 39141 | X16: 26355 | Y16: 26031 | Z16: 3332 | AA16: 75355 | AB16: 1555 | AC16: 37586 | AD16: 9 | AE16: 26346
A17: 4 | B17: 0.103546 | C17: 46 | D17: 86826 | E17: 91806 | F17: 78579 | G17: 38859 | H17: 26413 | I17: 26487 | J17: 3305 | K17: 75274 | L17: 1483 | M17: 37376 | N17: 10 | O17: 26403 | Q17: 4 | R17: 0.098145 | S17: 22 | T17: 86826 | U17: 91806 | V17: 78579 | W17: 38859 | X17: 26413 | Y17: 26487 | Z17: 3305 | AA17: 75274 | AB17: 1483 | AC17: 37376 | AD17: 10 | AE17: 26403
A18: 5 | B18: 0.108279 | C18: 39 | D18: 86820 | E18: 91650 | F18: 78879 | G18: 39253 | H18: 26352 | I18: 26010 | J18: 3340 | K18: 75539 | L18: 1531 | M18: 37722 | N18: 11 | O18: 26341 | Q18: 5 | R18: 0.09438 | S18: 22 | T18: 86820 | U18: 91650 | V18: 78879 | W18: 39253 | X18: 26352 | Y18: 26010 | Z18: 3340 | AA18: 75539 | AB18: 1531 | AC18: 37722 | AD18: 11 | AE18: 26341
A19: 6 | B19: 0.097433 | C19: 38 | D19: 87027 | E19: 92014 | F19: 78355 | G19: 39359 | H19: 26410 | I19: 26006 | J19: 3322 | K19: 75033 | L19: 1540 | M19: 37819 | N19: 3 | O19: 26407 | Q19: 6 | R19: 0.092988 | S19: 23 | T19: 87027 | U19: 92014 | V19: 78355 | W19: 39359 | X19: 26410 | Y19: 26006 | Z19: 3322 | AA19: 75033 | AB19: 1540 | AC19: 37819 | AD19: 3 | AE19: 26407
A20: 7 | B20: 0.10041 | C20: 40 | D20: 86407 | E20: 91403 | F20: 78729 | G20: 39261 | H20: 26286 | I20: 26465 | J20: 3310 | K20: 75419 | L20: 1494 | M20: 37767 | N20: 3 | O20: 26283 | Q20: 7 | R20: 0.114929 | S20: 22 | T20: 86407 | U20: 91403 | V20: 78729 | W20: 39261 | X20: 26286 | Y20: 26465 | Z20: 3310 | AA20: 75419 | AB20: 1494 | AC20: 37767 | AD20: 3 | AE20: 26283
A21: 8 | B21: 0.143083 | C21: 37 | D21: 86642 | E21: 91621 | F21: 78388 | G21: 39419 | H21: 26390 | I21: 26326 | J21: 3282 | K21: 75106 | L21: 1495 | M21: 37924 | N21: 6 | O21: 26384 | Q21: 8 | R21: 0.093854 | S21: 21 | T21: 86642 | U21: 91621 | V21: 78388 | W21: 39419 | X21: 26390 | Y21: 26326 | Z21: 3282 | AA21: 75106 | AB21: 1495 | AC21: 37924 | AD21: 6 | AE21: 26384
A22: 9 | B22: 0.097311 | C22: 40 | D22: 86703 | E22: 91740 | F22: 78509 | G22: 39237 | H22: 26292 | I22: 26366 | J22: 3338 | K22: 75171 | L22: 1522 | M22: 37715 | N22: 6 | O22: 26286 | Q22: 9 | R22: 0.091547 | S22: 22 | T22: 86703 | U22: 91740 | V22: 78509 | W22: 39237 | X22: 26292 | Y22: 26366 | Z22: 3338 | AA22: 75171 | AB22: 1522 | AC22: 37715 | AD22: 6 | AE22: 26286
A23: 10 | B23: 0.10785 | C23: 38 | D23: 86874 | E23: 91715 | F23: 78891 | G23: 39331 | H23: 26127 | I23: 26080 | J23: 3328 | K23: 75563 | L23: 1535 | M23: 37796 | N23: 2 | O23: 26125 | Q23: 10 | R23: 0.126413 | S23: 22 | T23: 86874 | U23: 91715 | V23: 78891 | W23: 39331 | X23: 26127 | Y23: 26080 | Z23: 3328 | AA23: 75563 | AB23: 1535 | AC23: 37796 | AD23: 2 | AE23: 26125
A24: 11 | B24: 0.129318 | C24: 38 | D24: 86838 | E24: 91865 | F24: 78376 | G24: 39277 | H24: 26371 | I24: 26255 | J24: 3255 | K24: 75121 | L24: 1512 | M24: 37765 | N24: 4 | O24: 26367 | Q24: 11 | R24: 0.112515 | S24: 22 | T24: 86838 | U24: 91865 | V24: 78376 | W24: 39277 | X24: 26371 | Y24: 26255 | Z24: 3255 | AA24: 75121 | AB24: 1512 | AC24: 37765 | AD24: 4 | AE24: 26367
A25: 12 | B25: 0.115993 | C25: 41 | D25: 86836 | E25: 91680 | F25: 78726 | G25: 39464 | H25: 26144 | I25: 26130 | J25: 3332 | K25: 75394 | L25: 1542 | M25: 37922 | N25: 9 | O25: 26135 | Q25: 12 | R25: 0.092148 | S25: 21 | T25: 86836 | U25: 91680 | V25: 78726 | W25: 39464 | X25: 26144 | Y25: 26130 | Z25: 3332 | AA25: 75394 | AB25: 1542 | AC25: 37922 | AD25: 9 | AE25: 26135
... A43: 30 | B43: 0.112201 | C43: 41 | D43: 86735 | E43: 91708 | F43: 78537 | G43: 39656 | H43: 26090 | I43: 26153 | J43: 3226 | K43: 75311 | L43: 1504 | M43: 38152 | N43: 6 | O43: 26084 | Q43: 30 | R43: 0.0983 | S43: 21 | T43: 86735 | U43: 91708 | V43: 78537 | W43: 39656 | X43: 26090 | Y43: 26153 | Z43: 3226 | AA43: 75311 | AB43: 1504 | AC43: 38152 | AD43: 6 | AE43: 26084

Sheet Inv_524288
A1: Resultados de Simulación para m = 524288
B3: Estadísticas de Tiempos y Alturas
B4: Métrica | C4: BST | D4: RedBlackBST
B5: Tiempo Mínimo (s) | C5: =MIN(B14:B43) -> 0 | D5: =MIN(R14:R43) -> 0
B6: Tiempo Máximo (s) | C6: =MAX(B14:B43) -> 0 | D6: =MAX(R14:R43) -> 0
B7: Tiempo Promedio (s) | C7: =AVERAGE(B14:B43) -> 0 | D7: =AVERAGE(R14:R43) -> 0
B8: Desviación Estándar (s) | C8: =STDEV.S(B14:B43) -> 0 | D8: =STDEV.S(R14:R43) -> 0
B9: Coeficiente de Variación | C9: =C7/C6 -> 0 | D9: =D7/D6 -> 0
B10: Altura Promedio | C10: =AVERAGE(C14:C43) -> 0 | D10: =AVERAGE(S14:S43) -> 0
B11: Altura Máxima | C11: =MAX(C14:C43) -> 0 | D11: =MAX(S14:S43) -> 0
A12: Microdatos de BST (30 Ejecuciones) | Q12: Microdatos de RedBlackBST (30 Ejecuciones)
A13: Instancia | B13: Tiempo (s) | C13: Altura Final | D13: Tamaño Final | E13: Compra Tot | F13: Cons Tot | G13: Prést Tot | H13: Dev Tot | I13: Baja Tot | J13: Cons Exit | K13: Cons Fall | L13: Prést Exit | M13: Prést Fall | N13: Dev Exit | O13: Dev Fall | Q13: Instancia | R13: Tiempo (s) | S13: Altura Final | T13: Tamaño Final | U13: Compra Tot | V13: Cons Tot | W13: Prést Tot | X13: Dev Tot | Y13: Baja Tot | Z13: Cons Exit | AA13: Cons Fall | AB13: Prést Exit | AC13: Prést Fall | AD13: Dev Exit | AE13: Dev Fall
A14: 1 | B14: 0.29862 | C14: 39 | D14: 173715 | E14: 183569 | F14: 157154 | G14: 78614 | H14: 52619 | I14: 52332 | J14: 6550 | K14: 150604 | L14: 3007 | M14: 75607 | N14: 16 | O14: 52603 | Q14: 1 | R14: 0.311176 | S14: 24 | T14: 173715 | U14: 183569 | V14: 157154 | W14: 78614 | X14: 52619 | Y14: 52332 | Z14: 6550 | AA14: 150604 | AB14: 3007 | AC14: 75607 | AD14: 16 | AE14: 52603
A15: 2 | B15: 0.326 | C15: 43 | D15: 174197 | E15: 184246 | F15: 156926 | G15: 78384 | H15: 51990 | I15: 52742 | J15: 6595 | K15: 150331 | L15: 2981 | M15: 75403 | N15: 16 | O15: 51974 | Q15: 2 | R15: 0.218227 | S15: 23 | T15: 174197 | U15: 184246 | V15: 156926 | W15: 78384 | X15: 51990 | Y15: 52742 | Z15: 6595 | AA15: 150331 | AB15: 2981 | AC15: 75403 | AD15: 16 | AE15: 51974
A16: 3 | B16: 0.247463 | C16: 40 | D16: 173806 | E16: 183649 | F16: 157034 | G16: 78917 | H16: 52464 | I16: 52224 | J16: 6684 | K16: 150350 | L16: 2877 | M16: 76040 | N16: 16 | O16: 52448 | Q16: 3 | R16: 0.230551 | S16: 23 | T16: 173806 | U16: 183649 | V16: 157034 | W16: 78917 | X16: 52464 | Y16: 52224 | Z16: 6684 | AA16: 150350 | AB16: 2877 | AC16: 76040 | AD16: 16 | AE16: 52448
A17: 4 | B17: 0.292635 | C17: 43 | D17: 173354 | E17: 183248 | F17: 157239 | G17: 78674 | H17: 52707 | I17: 52420 | J17: 6498 | K17: 150741 | L17: 2890 | M17: 75784 | N17: 13 | O17: 52694 | Q17: 4 | R17: 0.24961 | S17: 23 | T17: 173354 | U17: 183248 | V17: 157239 | W17: 78674 | X17: 52707 | Y17: 52420 | Z17: 6498 | AA17: 150741 | AB17: 2890 | AC17: 75784 | AD17: 13 | AE17: 52694
A18: 5 | B18: 0.333993 | C18: 42 | D18: 173126 | E18: 183052 | F18: 157684 | G18: 78508 | H18: 52376 | I18: 52668 | J18: 6499 | K18: 151185 | L18: 2987 | M18: 75521 | N18: 15 | O18: 52361 | Q18: 5 | R18: 0.287494 | S18: 24 | T18: 173126 | U18: 183052 | V18: 157684 | W18: 78508 | X18: 52376 | Y18: 52668 | Z18: 6499 | AA18: 151185 | AB18: 2987 | AC18: 75521 | AD18: 15 | AE18: 52361
A19: 6 | B19: 0.287169 | C19: 41 | D19: 173682 | E19: 183607 | F19: 157193 | G19: 78490 | H19: 52277 | I19: 52721 | J19: 6716 | K19: 150477 | L19: 3028 | M19: 75462 | N19: 15 | O19: 52262 | Q19: 6 | R19: 0.312644 | S19: 23 | T19: 173682 | U19: 183607 | V19: 157193 | W19: 78490 | X19: 52277 | Y19: 52721 | Z19: 6716 | AA19: 150477 | AB19: 3028 | AC19: 75462 | AD19: 15 | AE19: 52262
A20: 7 | B20: 0.25423 | C20: 42 | D20: 173605 | E20: 183451 | F20: 157283 | G20: 78725 | H20: 52597 | I20: 52232 | J20: 6714 | K20: 150569 | L20: 3009 | M20: 75716 | N20: 14 | O20: 52583 | Q20: 7 | R20: 0.22528 | S20: 24 | T20: 173605 | U20: 183451 | V20: 157283 | W20: 78725 | X20: 52597 | Y20: 52232 | Z20: 6714 | AA20: 150569 | AB20: 3009 | AC20: 75716 | AD20: 14 | AE20: 52583
A21: 8 | B21: 0.302559 | C21: 42 | D21: 173365 | E21: 183211 | F21: 157561 | G21: 78631 | H21: 52751 | I21: 52134 | J21: 6620 | K21: 150941 | L21: 3038 | M21: 75593 | N21: 10 | O21: 52741 | Q21: 8 | R21: 0.208604 | S21: 23 | T21: 173365 | U21: 183211 | V21: 157561 | W21: 78631 | X21: 52751 | Y21: 52134 | Z21: 6620 | AA21: 150941 | AB21: 3038 | AC21: 75593 | AD21: 10 | AE21: 52741
A22: 9 | B22: 0.255967 | C22: 42 | D22: 173720 | E22: 183589 | F22: 157329 | G22: 78646 | H22: 52405 | I22: 52319 | J22: 6698 | K22: 150631 | L22: 2947 | M22: 75699 | N22: 16 | O22: 52389 | Q22: 9 | R22: 0.255659 | S22: 23 | T22: 173720 | U22: 183589 | V22: 157329 | W22: 78646 | X22: 52405 | Y22: 52319 | Z22: 6698 | AA22: 150631 | AB22: 2947 | AC22: 75699 | AD22: 16 | AE22: 52389
A23: 10 | B23: 0.339905 | C23: 42 | D23: 173622 | E23: 183678 | F23: 157314 | G23: 78547 | H23: 52399 | I23: 52350 | J23: 6631 | K23: 150683 | L23: 2998 | M23: 75549 | N23: 13 | O23: 52386 | Q23: 10 | R23: 0.25773 | S23: 24 | T23: 173622 | U23: 183678 | V23: 157314 | W23: 78547 | X23: 52399 | Y23: 52350 | Z23: 6631 | AA23: 150683 | AB23: 2998 | AC23: 75549 | AD23: 13 | AE23: 52386
A24: 11 | B24: 0.219724 | C24: 43 | D24: 173143 | E24: 183034 | F24: 157650 | G24: 78799 | H24: 52553 | I24: 52252 | J24: 6566 | K24: 151084 | L24: 2987 | M24: 75812 | N24: 18 | O24: 52535 | Q24: 11 | R24: 0.283627 | S24: 23 | T24: 173143 | U24: 183034 | V24: 157650 | W24: 78799 | X24: 52553 | Y24: 52252 | Z24: 6566 | AA24: 151084 | AB24: 2987 | AC24: 75812 | AD24: 18 | AE24: 52535
A25: 12 | B25: 0.252739 | C25: 42 | D25: 173650 | E25: 183607 | F25: 157823 | G25: 77977 | H25: 52228 | I25: 52653 | J25: 6658 | K25: 151165 | L25: 2858 | M25: 75119 | N25: 8 | O25: 52220 | Q25: 12 | R25: 0.217029 | S25: 23 | T25: 173650 | U25: 183607 | V25: 157823 | W25: 77977 | X25: 52228 | Y25: 52653 | Z25: 6658 | AA25: 151165 | AB25: 2858 | AC25: 75119 | AD25: 8 | AE25: 52220
... A43: 30 | B43: 0.279172 | C43: 43 | D43: 173402 | E43: 183496 | F43: 157068 | G43: 78561 | H43: 52545 | I43: 52618 | J43: 6605 | K43: 150463 | L43: 3010 | M43: 75551 | N43: 16 | O43: 52529 | Q43: 30 | R43: 0.254136 | S43: 23 | T43: 173402 | U43: 183496 | V43: 157068 | W43: 78561 | X43: 52545 | Y43: 52618 | Z43: 6605 | AA43: 150463 | AB43: 3010 | AC43: 75551 | AD43: 16 | AE43: 52529
